<?xml version="1.0"?>
<robot xmlns:xacro="http://www.ros.org/wiki/xacro" name="swarm_bot">

  <xacro:arg name="robot_ns" default="robot_1"/>
  <xacro:property name="ns" value="$(arg robot_ns)"/>

  <xacro:property name="chassis_length" value="0.30"/>
  <xacro:property name="chassis_width"  value="0.20"/>
  <xacro:property name="chassis_height" value="0.08"/>
  <xacro:property name="chassis_mass"   value="2.0"/>
  <xacro:property name="chassis_z"      value="0.06"/>

  <xacro:property name="wheel_radius" value="0.04"/>
  <xacro:property name="wheel_width"  value="0.02"/>
  <xacro:property name="wheel_mass"   value="0.2"/>
  <xacro:property name="wheel_y_offset" value="0.11"/>

  <xacro:property name="caster_radius" value="0.02"/>

  <xacro:property name="lidar_z" value="0.12"/>

  <xacro:property name="camera_x" value="0.16"/>
  <xacro:property name="camera_z" value="0.10"/>

  <material name="blue">
    <color rgba="0.2 0.4 0.8 1.0"/>
  </material>
  <material name="black">
    <color rgba="0.05 0.05 0.05 1.0"/>
  </material>
  <material name="dark_grey">
    <color rgba="0.3 0.3 0.3 1.0"/>
  </material>
  <material name="red">
    <color rgba="0.8 0.1 0.1 1.0"/>
  </material>
  <material name="green">
    <color rgba="0.1 0.8 0.1 1.0"/>
  </material>

  <xacro:macro name="box_inertia" params="m w h d">
    <inertial>
      <mass value="${m}"/>
      <inertia ixx="${(m/12)*(h*h+d*d)}" ixy="0" ixz="0"
               iyy="${(m/12)*(w*w+d*d)}" iyz="0"
               izz="${(m/12)*(w*w+h*h)}"/>
    </inertial>
  </xacro:macro>

  <xacro:macro name="cylinder_inertia" params="m r h">
    <inertial>
      <mass value="${m}"/>
      <inertia ixx="${(m/12)*(3*r*r+h*h)}" ixy="0" ixz="0"
               iyy="${(m/12)*(3*r*r+h*h)}" iyz="0"
               izz="${(m/2)*r*r}"/>
    </inertial>
  </xacro:macro>

  <xacro:macro name="sphere_inertia" params="m r">
    <inertial>
      <mass value="${m}"/>
      <inertia ixx="${(2*m/5)*r*r}" ixy="0" ixz="0"
               iyy="${(2*m/5)*r*r}" iyz="0"
               izz="${(2*m/5)*r*r}"/>
    </inertial>
  </xacro:macro>

  <link name="base_footprint"/>

  <joint name="base_joint" type="fixed">
    <parent link="base_footprint"/>
    <child link="base_link"/>
    <origin xyz="0 0 ${chassis_z}" rpy="0 0 0"/>
  </joint>

  <link name="base_link">
    <visual>
      <geometry>
        <box size="${chassis_length} ${chassis_width} ${chassis_height}"/>
      </geometry>
      <material name="black"/>
    </visual>
    <collision>
      <geometry>
        <box size="${chassis_length} ${chassis_width} ${chassis_height}"/>
      </geometry>
    </collision>
    <xacro:box_inertia m="${chassis_mass}" w="${chassis_width}" h="${chassis_height}" d="${chassis_length}"/>
  </link>

  <gazebo reference="base_link">
    <material>Gazebo/Black</material>
  </gazebo>

  <xacro:macro name="drive_wheel" params="prefix y_offset">
    <link name="${prefix}_wheel">
      <visual>
        <geometry>
          <cylinder radius="${wheel_radius}" length="${wheel_width}"/>
        </geometry>
        <material name="dark_grey"/>
      </visual>
      <collision>
        <geometry>
          <cylinder radius="${wheel_radius}" length="${wheel_width}"/>
        </geometry>
      </collision>
      <xacro:cylinder_inertia m="${wheel_mass}" r="${wheel_radius}" h="${wheel_width}"/>
    </link>

    <joint name="${prefix}_wheel_joint" type="continuous">
      <parent link="base_link"/>
      <child link="${prefix}_wheel"/>
      <origin xyz="0 ${y_offset} ${-chassis_z + wheel_radius}" rpy="${-pi/2} 0 0"/>
      <axis xyz="0 0 1"/>
      <dynamics damping="0.1" friction="0.1"/>
    </joint>

    <gazebo reference="${prefix}_wheel">
      <material>Gazebo/DarkGrey</material>
      <mu1>1.0</mu1>
      <mu2>1.0</mu2>
    </gazebo>
  </xacro:macro>

  <xacro:drive_wheel prefix="left"  y_offset="${wheel_y_offset}"/>
  <xacro:drive_wheel prefix="right" y_offset="${-wheel_y_offset}"/>

  <link name="caster_wheel">
    <visual>
      <geometry>
        <sphere radius="${caster_radius}"/>
      </geometry>
      <material name="dark_grey"/>
    </visual>
    <collision>
      <geometry>
        <sphere radius="${caster_radius}"/>
      </geometry>
    </collision>
    <xacro:sphere_inertia m="0.05" r="${caster_radius}"/>
  </link>

  <joint name="caster_wheel_joint" type="fixed">
    <parent link="base_link"/>
    <child link="caster_wheel"/>
    <origin xyz="${-chassis_length/2 + caster_radius + 0.01} 0 ${-chassis_z + caster_radius}" rpy="0 0 0"/>
  </joint>

  <gazebo reference="caster_wheel">
    <material>Gazebo/DarkGrey</material>
    <mu1>0.0</mu1>
    <mu2>0.0</mu2>
  </gazebo>

  <link name="lidar_link">
    <visual>
      <geometry>
        <cylinder radius="0.03" length="0.02"/>
      </geometry>
      <material name="red"/>
    </visual>
    <collision>
      <geometry>
        <cylinder radius="0.03" length="0.02"/>
      </geometry>
    </collision>
    <xacro:cylinder_inertia m="0.05" r="0.03" h="0.02"/>
  </link>

  <joint name="lidar_joint" type="fixed">
    <parent link="base_link"/>
    <child link="lidar_link"/>
    <origin xyz="0 0 ${chassis_height/2 + 0.01}" rpy="0 0 0"/>
  </joint>

  <gazebo reference="lidar_link">
    <material>Gazebo/Red</material>
    <sensor type="ray" name="lidar_sensor">
      <pose>0 0 0 0 0 0</pose>
      <visualize>false</visualize>
      <update_rate>10</update_rate>
      <ray>
        <scan>
          <horizontal>
            <samples>360</samples>
            <resolution>1</resolution>
            <min_angle>-3.14159</min_angle>
            <max_angle>3.14159</max_angle>
          </horizontal>
        </scan>
        <range>
          <min>0.12</min>
          <max>3.5</max>
          <resolution>0.01</resolution>
        </range>
        <noise>
          <type>gaussian</type>
          <mean>0.0</mean>
          <stddev>0.01</stddev>
        </noise>
      </ray>
      <plugin name="gazebo_ros_lidar" filename="libgazebo_ros_ray_sensor.so">
        <ros>
          <namespace>${ns}</namespace>
          <remapping>~/out:=scan</remapping>
        </ros>
        <output_type>sensor_msgs/LaserScan</output_type>
        <frame_name>${ns}/lidar_link</frame_name>
      </plugin>
    </sensor>
  </gazebo>

  <link name="camera_link">
    <visual>
      <geometry>
        <box size="0.02 0.06 0.02"/>
      </geometry>
      <material name="green"/>
    </visual>
    <collision>
      <geometry>
        <box size="0.02 0.06 0.02"/>
      </geometry>
    </collision>
    <xacro:box_inertia m="0.03" w="0.06" h="0.02" d="0.02"/>
  </link>

  <joint name="camera_joint" type="fixed">
    <parent link="base_link"/>
    <child link="camera_link"/>
    <origin xyz="${chassis_length/2} 0 ${chassis_height/4}" rpy="0 0 0"/>
  </joint>

  <link name="camera_optical_link"/>
  <joint name="camera_optical_joint" type="fixed">
    <parent link="camera_link"/>
    <child link="camera_optical_link"/>
    <origin xyz="0 0 0" rpy="${-pi/2} 0.3 ${-pi/2}"/>
  </joint>

  <gazebo reference="camera_link">
    <material>Gazebo/Green</material>
    <sensor type="depth" name="rgbd_camera">
      <update_rate>10</update_rate>
      <camera name="camera">
        <horizontal_fov>1.047</horizontal_fov>
        <image>
          <width>640</width>
          <height>480</height>
          <format>R8G8B8</format>
        </image>
        <clip>
          <near>0.05</near>
          <far>8.0</far>
        </clip>
        <noise>
          <type>gaussian</type>
          <mean>0.0</mean>
          <stddev>0.007</stddev>
        </noise>
      </camera>
      <plugin name="gazebo_ros_camera" filename="libgazebo_ros_camera.so">
        <ros>
          <namespace>${ns}</namespace>
        </ros>
        <camera_name>camera</camera_name>
        <frame_name>${ns}/camera_optical_link</frame_name>
        <hack_baseline>0.07</hack_baseline>
        <min_depth>0.05</min_depth>
        <max_depth>8.0</max_depth>
      </plugin>
    </sensor>
  </gazebo>

  <gazebo>
    <plugin name="diff_drive_controller" filename="libgazebo_ros_diff_drive.so">
      <ros>
        <namespace>${ns}</namespace>
      </ros>
      <update_rate>30</update_rate>
      <left_joint>left_wheel_joint</left_joint>
      <right_joint>right_wheel_joint</right_joint>
      <wheel_separation>${2 * wheel_y_offset}</wheel_separation>
      <wheel_diameter>${2 * wheel_radius}</wheel_diameter>
      <max_wheel_torque>5.0</max_wheel_torque>
      <max_wheel_acceleration>2.0</max_wheel_acceleration>
      <command_topic>cmd_vel</command_topic>
      <publish_odom>true</publish_odom>
      <publish_odom_tf>true</publish_odom_tf>
      <publish_wheel_tf>false</publish_wheel_tf>
      <odometry_topic>odom</odometry_topic>
      <odometry_frame>${ns}/odom</odometry_frame>
      <robot_base_frame>${ns}/base_footprint</robot_base_frame>
    </plugin>
  </gazebo>

</robot>
